Workbook

Sheet 01
A1: =CONCATENATE("Ежедневный отчет производства и отгрузки за 01 ",Q1) -> Ежедневный отчет производства и отгрузки за 01 август | Q1: август
Q2: 31
A3: Наименование | B3: ЕдИзм | C3: План на месяц | D3: Остатки на складе на начало месяца | E3: Производство/поступление | J3: Отгружено со склада/отпущено в производство/перемещение | L3: Остаток на складе на конец суток | M3: Акты ОКК о переводе марок/перемещение между складами | N3: Перемещения | O3: Комментарии
E4: план на сутки | F4: факт за сутки | G4: план с начала месяца | H4: факт с начала месяца | I4: % | J4: факт за сутки | K4: факт с начала месяца
A5: Клинкер всего | B5: т | C5: =C6+C9 -> 160800 | D5: =D6+D9+D8 -> 143025.21 | E5: =E6+E9 -> 6700 | F5: =F6+F9 -> 6289.0515 | G5: =G6+G9 -> 6700 | H5: =H6+H9 -> 6289.0515 | I5: =IFERROR((H5/G5),0) -> 0.93866441 | J5: =J6+J9 -> 6404.3194 | K5: =K6+K9+K8 -> 6404.3194 | L5: =L6+L9+L8 -> 142909.95
A6: Клинкер грейферный склад | B6: т | C6: 0 | D6: 15952.92 | E6: 0 | G6: =E6 -> 0 | H6: =F6 -> 0 | K6: =J6 -> 0 | L6: =D6+H6-K6-M6+N6 -> 15952.92 | N6: 0
A7: Клинкер некондиция (шихта) | B7: т | D7: 0 | F7: 0 | H7: =F7 -> 0 | K7: =J7 -> 0 | L7: =D7+H7-K7-M7+N7 -> 0
A8: клинкер некондиционный склад БСУ | B8: т | D8: 0 | H8: =F8 -> 0 | K8: =J8 -> 0 | L8: =D8+H8-K8 -> 0
A9: Клинкер сухой линии в т.ч.: | B9: т | C9: 160800 | D9: =D10+D11+D12+D13 -> 127072.29 | E9: 6700 | F9: =F10+F11+F12+F13 -> 6289.0515 | G9: =E9 -> 6700 | H9: =H10+H11+H12+H13 -> 6289.0515 | I9: =IFERROR((H9/G9),0) -> 0.93866441 | J9: =J10+J11+J12+J13 -> 6404.3194 | K9: =K10+K11+K12+K13 -> 6404.3194 | L9: =D9+H9-K9+M9-N9 -> 126957.03 | N9: 0 | Q9: -23266.572 | R9: =J9-Q9 -> 29670.891
A10: клинкер в силосе | B10: т | D10: 56300.274 | F10: 6289.0515 | G10: =E10 -> 0 | H10: =F10 -> 6289.0515 | J10: 6404.3194 | K10: =J10 -> 6404.3194 | L10: =D10+H10-K10 -> 56185.006
A11: Клинкер СС грейферный склад | B11: т | D11: 18224.017 | G11: =E11 -> 0 | H11: =F11 -> 0 | J11: 0 | K11: =J11 -> 0 | L11: =D11+H11-K11 -> 18224.017
A12: клинкер на площадку (за шатровый склад) | B12: т | C12: 0 | D12: 52548.003 | E12: =C12/31 -> 0 | G12: =E12 -> 0 | H12: =F12 -> 0 | I12: =IFERROR((H12/G12),0) -> 0 | K12: =J12 -> 0 | L12: =D12+H12-K12 -> 52548.003
A13: клинкер на площадку (лессовый) | B13: т | D13: 0 | H13: =F13 -> 0 | K13: =J13 -> 0 | L13: =D13+H13-K13 -> 0
A14: Цемент в силосах всего, в том числе: | B14: т | C14: =SUM(C15:C21) -> 195040 | D14: =SUM(D15:D21) -> 25904.614 | E14: =SUM(E15:E21) -> 5044 | F14: =SUM(F15:F21) -> 6863.1288 | G14: =SUM(G15:G21) -> 5044 | H14: =SUM(H15:H21) -> 6863.1288 | I14: =IFERROR((H14/G14),0) -> 1.360652 | J14: =SUM(J15:J21) -> 6788.8 | K14: =SUM(K15:K21) -> 6788.8 | L14: =SUM(L15:L21) -> 25978.943 | S14: Клинкер фактор | T14: =J5/F14 -> 0.93314866
A15: ЦЕМ II/А-Г 32.5Н | B15: т | C15: 0 | D15: 0 | E15: 0 | F15: 0 | G15: =E15 -> 0 | H15: =F15 -> 0 | I15: =IFERROR((H15/G15),0) -> 0 | J15: 0 | K15: =J15 -> 0 | L15: =D15+H15-K15+M15 -> 0
A16: ЦEМ II/B-K(З-И) 42,5H | B16: т | C16: 44352 | D16: 6069.3573 | E16: 1147.0031 | F16: 33.198514 | G16: =E16 -> 1147.0031 | H16: =F16 -> 33.198514 | I16: =IFERROR((H16/G16),0) -> 0.0289437 | J16: =IFERROR(SUMIF(A101:A114,A16,E101:E114),0)+E111+E112+E113 -> 1345.25 | K16: =J16 -> 1345.25 | L16: =D16+H16-K16+M16 -> 4757.3058
A17: AMD - 1000 | B17: т | C17: 0 | D17: 483.2374 | E17: 0 | F17: 0 | G17: =E17 -> 0 | H17: =F17 -> 0 | I17: =IFERROR((H17/G17),0) -> 0 | J17: =IFERROR(SUMIF(A102:A115,A17,E102:E115),0)+E116+E119+E121+E114 -> 0 | K17: =J17 -> 0 | L17: =D17+H17-K17+M17 -> 483.2374 | S17: Коэф. мука-клинкер | T17: =O51/F5 -> 1.644746
A18: ЦEМ II/B-K(З-И) 32,5H | B18: т | C18: 1360 | D18: 3183.2381 | G18: =E18 -> 0 | H18: =F18 -> 0 | I18: =IFERROR((H18/G18),0) -> 0 | J18: =IFERROR(SUMIF(A102:A115,A18,E102:E115),0)+E118+E120 -> 0 | K18: =J18 -> 0 | L18: =D18+H18-K18+M18 -> 3183.2381
A19: ЦЕМ I 52.5Н | B19: т | C19: 145770 | D19: 12764.734 | E19: 3769.8107 | F19: 6829.9303 | G19: =E19 -> 3769.8107 | H19: =F19 -> 6829.9303 | I19: =IFERROR((H19/G19),0) -> 1.8117436 | J19: =IFERROR(SUMIF(A102:A115,A19,E102:E115),0)+E117+E115+E122 -> 5443.55 | K19: =J19 -> 5443.55 | L19: =D19+H19-K19+M19 -> 14151.114
A20: ЦЕМ I 42.5Н СС | B20: т | C20: 3558 | D20: 3404.048 | E20: 92.014725 | F20: 0 | G20: =E20 -> 92.014725 | H20: =F20 -> 0 | I20: =IFERROR((H20/G20),0) -> 0 | J20: =IFERROR(SUMIF(A102:A115,A20,E102:E115),0) -> 0 | K20: =J20 -> 0 | L20: =D20+H20-K20+M20 -> 3404.048
A21: ЦЕМ I 42.5Н | B21: т | C21: 0 | D21: 8.7766239e-11 | E21: 35.171452 | F21: 0 | G21: =E21 -> 35.171452 | H21: =F21 -> 0 | I21: =IFERROR((H21/G21),0) -> 0 | J21: =IFERROR(SUMIF(A102:A115,A21,E102:E115),0) -> 0 | K21: =J21 -> 0 | L21: =D21+H21-K21-M21 -> 8.7766239e-11
A22: AMD - 6 (навал) | C22: 1100 | D22: 2833.7506 | E22: 0 | F22: 0 | G22: =E22 -> 0 | H22: =F22 -> 0 | J22: =IFERROR(SUMIF(A103:A123,A22,E103:E123),0)+E109 -> 449.6 | K22: =J22 -> 449.6 | L22: =D22+H22-K22-M22 -> 2384.1506
A23: Тара: МКР | B23: т | C23: 0 | D23: =SUM(D24:D27) -> 52 | E23: 0 | F23: =SUM(F24:F29) -> 0 | G23: =E23 -> 0 | H23: =SUM(H24:H29) -> 0 | I23: =IFERROR((H23/G23),0) -> 0 | J23: =SUM(J24:J29) -> 0 | K23: =J23 -> 0 | L23: =D23+H23-K23+M23 -> 52
A24: ЦEМ II/А-K(З-И) 42,5H Портландцемент композиционный (МКР) | B24: т | D24: 0 | F24: 0 | G24: =E24 -> 0 | H24: =F24 -> 0 | J24: 0 | K24: =J24 -> 0 | L24: =D24+H24-K24-M24 -> 0
A25: ЦEМ II/B-K(З-И) 42,5H Портландцемент композиционный (МКР) | B25: т | D25: 16 | F25: 0 | G25: =E25 -> 0 | H25: =F25 -> 0 | J25: 0 | K25: =J25 -> 0 | L25: =D25+H25-K25-M25 -> 16
A26: ЦEМ I 52,5H Портландцемент (МКР) | B26: т | D26: 36 | F26: 0 | G26: =E26 -> 0 | H26: =F26 -> 0 | J26: 0 | K26: =J26 -> 0 | L26: =D26+H26-K26-M26 -> 36
A27: ЦЕМ I 42.5Н | B27: т | D27: 0 | F27: 0 | G27: =E27 -> 0 | H27: =F27 -> 0 | K27: =J27 -> 0 | L27: =D27+H27-K27-M27 -> 0
B28: т | F28: =J28 -> 0 | G28: =E28 -> 0 | H28: =F28 -> 0 | K28: =J28 -> 0 | L28: =D28+H28-K28-M28 -> 0
B29: т | F29: =J29 -> 0 | G29: =E29 -> 0 | H29: =F29 -> 0 | K29: =J29 -> 0 | L29: =D29+H29-K29-M29 -> 0
A30: Тара: паллеты | B30: т | D30: =SUM(D31:D34) -> 1513.6 | F30: =SUM(F31:F37) -> 197.12 | G30: =E30 -> 0 | H30: =SUM(H31:H37) -> 197.12 | I30: =IFERROR((H30/G30),0) -> 0 | J30: =SUM(J31:J37) -> 519.2 | K30: =J30 -> 519.2 | L30: =D30+H30-K30-M30 -> 1191.52
A31: ЦЕМ II/А-К (З-И) 42,5Н | B31: т | D31: 0 | F31: 0 | G31: =E31 -> 0 | H31: =F31 -> 0 | J31: 0 | K31: =J31 -> 0 | L31: =D31+H31-K31-M31 -> 0 | T31: =300+T30 -> 300
A32: ЦEМ II/B-K(З-И) 42,5H | B32: т | D32: 1508.32 | F32: 197.12 | G32: =E32 -> 0 | H32: =F32 -> 197.12 | J32: 519.2 | K32: =J32 -> 519.2 | L32: =D32+H32-K32-M32 -> 1186.24
A33: ЦЕМ I 52.5Н | B33: т | D33: 5.28 | F33: 0 | G33: =E33 -> 0 | H33: =F33 -> 0 | J33: 0 | K33: =J33 -> 0 | L33: =D33+H33-K33-M33 -> 5.28
A34: ЦЕМ I 42.5Н | B34: т | D34: 0 | F34: 0 | G34: =E34 -> 0 | H34: =F34 -> 0 | K34: =J34 -> 0 | L34: =D34+H34-K34-M34 -> 0
B35: т | F35: =J35 -> 0 | G35: =E35 -> 0 | H35: =F35 -> 0 | K35: =J35 -> 0 | L35: =D35+H35-K35-M35 -> 0
A36: Песок природный | B36: т | C36: 3500 | D36: 1673.24 | F36: =J36 -> 0 | G36: =E36 -> 0 | J36: 0 | K36: =J36 -> 0 | L36: =D36+H36-K36-M36 -> 1673.24
A37: Щебень фракции 5-20 | B37: т | C37: 0 | D37: 294.64 | F37: =J37 -> 0 | G37: =E37 -> 0 | J37: 0 | K37: =J37 -> 0 | L37: =D37+H37-K37-M37 -> 294.64
A38: Известняк общий: | B38: т | C38: 153958.11 | D38: 1756.983 | E38: =C38/31 -> 4966.3906 | F38: =SUM(F39:F41) -> 2448.1896 | G38: =E38 -> 4966.3906 | H38: =F38 -> 2448.1896 | I38: =IFERROR((H38/G38),0) -> 0.49295149 | J38: =SUM(J39:J40) -> 2448.1896 | K38: =SUM(K39:K40) -> 2448.1896 | L38: =D38+H38-K38 -> 1756.983
A39: известняк на шатровый склад | B39: т | D39: 0 | F39: 2448.1896 | H39: =F39 -> 2448.1896 | J39: =F39 -> 2448.1896 | K39: =J39 -> 2448.1896
A40: известняк на помол | B40: т | F40: 0 | H40: =F40 -> 0 | J40: 0 | K40: =J40 -> 0
...

Sheet 02
A1: =CONCATENATE("Ежедневный отчет производства и отгрузки за 02 ",Q1) -> Ежедневный отчет производства и отгрузки за 02 август | Q1: август
Q2: 31
A3: Наименование | B3: ЕдИзм | C3: План на месяц | D3: Остатки на складе на начало месяца | E3: Производство/поступление | J3: Отгружено со склада/отпущено в производство/перемещение | L3: Остаток на складе на конец суток | M3: Акты ОКК о переводе марок/перемещение между складами | N3: Перемещения | O3: Комментарии
E4: план на сутки | F4: факт за сутки | G4: план с начала месяца | H4: факт с начала месяца | I4: % | J4: факт за сутки | K4: факт с начала месяца
A5: Клинкер всего | B5: т | C5: =C6+C9 -> 160800 | D5: =D6+D9+D8 -> 143025.21 | E5: =E6+E9 -> 6700 | F5: =F6+F9 -> 4249.76 | G5: =G6+G9 -> 13400 | H5: =H6+H9 -> 10538.812 | I5: =IFERROR((H5/G5),0) -> 0.78647847 | J5: =J6+J9 -> 6917.2044 | K5: =K6+K9+K8 -> 13321.524 | L5: =L6+L9+L8 -> 140242.5
A6: Клинкер грейферный склад | B6: т | C6: ='01'!C6 -> 0 | D6: ='01'!D6 -> 15952.92 | E6: 0 | G6: =E6+'01'!G6 -> 0 | H6: =F6+'01'!H6 -> 0 | K6: =J6+'01'!K6 -> 0 | L6: =D6+H6-K6-M6+N6 -> 15952.92 | N6: 0
A7: Клинкер некондиция (шихта) | B7: т | D7: ='01'!D7 -> 0 | F7: 0 | H7: =F7+'01'!H7 -> 0 | K7: =J7+'01'!K7 -> 0 | L7: =D7+H7-K7-M7+N7 -> 0
A8: клинкер некондиционный склад БСУ | B8: т | D8: ='01'!D8 -> 0 | H8: =F8+'01'!H8 -> 0 | K8: =J8+'01'!K8 -> 0 | L8: =D8+H8-K8 -> 0
A9: Клинкер сухой линии в т.ч.: | B9: т | C9: ='01'!C9 -> 160800 | D9: ='01'!D9 -> 127072.29 | E9: 6700 | F9: =F10+F11+F12+F13 -> 4249.76 | G9: =E9+'01'!G9 -> 13400 | H9: =F9+'01'!H9 -> 10538.812 | I9: =IFERROR((H9/G9),0) -> 0.78647847 | J9: =J10+J11+J12+J13 -> 6917.2044 | K9: =J9+'01'!K9 -> 13321.524 | L9: =D9+H9-K9+M9-N9 -> 124289.58 | N9: 0 | Q9: -23266.572 | R9: =J9-Q9 -> 30183.776
A10: клинкер в силосе | B10: т | D10: ='01'!D10 -> 56300.274 | F10: 4249.76 | G10: =E10+'01'!G10 -> 0 | H10: =F10+'01'!H10 -> 10538.812 | J10: 6917.2044 | K10: =J10+'01'!K10 -> 13321.524 | L10: =D10+H10-K10+M10-N10 -> 53517.562
A11: Клинкер СС грейферный склад | B11: т | D11: ='01'!D11 -> 18224.017 | G11: =E11+'01'!G11 -> 0 | H11: =F11+'01'!H11 -> 0 | J11: 0 | K11: =J11+'01'!K11 -> 0 | L11: =D11+H11-K11+M11-N11 -> 18224.017
A12: клинкер на площадку (за шатровый склад) | B12: т | D12: ='01'!D12 -> 52548.003 | E12: =C12/31 -> 0 | G12: =E12+'01'!G12 -> 0 | H12: =F12+'01'!H12 -> 0 | I12: =IFERROR((H12/G12),0) -> 0 | K12: =J12+'01'!K12 -> 0 | L12: =D12+H12-K12+M12-N12 -> 52548.003
A13: клинкер на площадку (лессовый) | B13: т | D13: ='01'!D13 -> 0 | H13: =F13+'01'!H13 -> 0 | K13: =J13+'01'!K13 -> 0 | L13: =D13+H13-K13+M13-N13 -> 0
A14: Цемент в силосах всего, в том числе: | B14: т | C14: =SUM(C15:C21) -> 195040 | D14: ='01'!D14 -> 25904.614 | E14: =SUM(E15:E21) -> 4798 | F14: =SUM(F15:F21) -> 7877.0326 | G14: =SUM(G15:G21) -> 9842 | H14: =SUM(H15:H21) -> 14740.161 | I14: =IFERROR((H14/G14),0) -> 1.4976795 | J14: =SUM(J15:J21) -> 4988.87 | K14: =SUM(K15:K21) -> 11777.67 | L14: =SUM(L15:L21) -> 28867.106 | S14: Клинкер фактор | T14: =J5/F14 -> 0.87814851
A15: ЦЕМ II/А-Г 32.5Н | B15: т | C15: ='01'!C15 -> 0 | D15: ='01'!D15 -> 0 | E15: 0 | F15: 0 | G15: =E15+'01'!G15 -> 0 | H15: =F15+'01'!H15 -> 0 | I15: =IFERROR((H15/G15),0) -> 0 | J15: 0 | K15: =J15+'01'!K15 -> 0 | L15: =D15+H15-K15+M15 -> 0
A16: ЦEМ II/B-K(З-И) 42,5H | B16: т | C16: ='01'!C16 -> 44352 | D16: ='01'!D16 -> 6069.3573 | E16: 1091.0628 | F16: 2450.5299 | G16: =E16+'01'!G16 -> 2238.066 | H16: =F16+'01'!H16 -> 2483.7284 | I16: =IFERROR((H16/G16),0) -> 1.1097655 | J16: =IFERROR(SUMIF(A101:A114,A16,E101:E114),0)+E111+E112+E113 -> 673.02 | K16: =J16+'01'!K16 -> 2018.27 | L16: =D16+H16-K16+M16 -> 6534.8157
A17: AMD - 1000 | B17: т | C17: ='01'!C17 -> 0 | D17: ='01'!D17 -> 483.2374 | E17: 0 | F17: 0 | G17: =E17+'01'!G17 -> 0 | H17: =F17+'01'!H17 -> 0 | I17: =IFERROR((H17/G17),0) -> 0 | J17: =IFERROR(SUMIF(A102:A115,A17,E102:E115),0)+E116+E119+E121+E114 -> 0 | K17: =J17+'01'!K17 -> 0 | L17: =D17+H17-K17+M17 -> 483.2374 | S17: Коэф. мука-клинкер | T17: =O51/F5 -> 1.6232982
A18: ЦEМ II/B-K(З-И) 32,5H | B18: т | C18: ='01'!C18 -> 1360 | D18: ='01'!D18 -> 3183.2381 | G18: =E18+'01'!E18 -> 0 | H18: =F18+'01'!H18 -> 0 | I18: =IFERROR((H18/G18),0) -> 0 | J18: =IFERROR(SUMIF(A102:A115,A18,E102:E115),0)+E118+E120 -> 0 | K18: =J18+'01'!K18 -> 0 | L18: =D18+H18-K18+M18 -> 3183.2381
A19: ='01'!A19 -> ЦЕМ I 52.5Н | B19: т | C19: ='01'!C19 -> 145770 | D19: ='01'!D19 -> 12764.734 | E19: 3585.954 | F19: 5426.5027 | G19: =E19+'01'!G19 -> 7355.7647 | H19: =F19+'01'!H19 -> 12256.433 | I19: =IFERROR((H19/G19),0) -> 1.6662351 | J19: =IFERROR(SUMIF(A102:A115,A19,E102:E115),0)+E117+E115+E122 -> 4088.8 | K19: =J19+'01'!K19 -> 9532.35 | L19: =D19+H19-K19+M19 -> 15488.817
A20: ЦЕМ I 42.5Н СС | B20: т | C20: ='01'!C20 -> 3558 | D20: ='01'!D20 -> 3404.048 | E20: 87.527092 | F20: 0 | G20: =E20+'01'!G20 -> 179.54182 | H20: =F20+'01'!H20 -> 0 | I20: =IFERROR((H20/G20),0) -> 0 | J20: =IFERROR(SUMIF(A102:A115,A20,E102:E115),0) -> 227.05 | K20: =J20+'01'!K20 -> 227.05 | L20: =D20+H20-K20+M20 -> 3176.998
A21: ='01'!A21 -> ЦЕМ I 42.5Н | B21: т | C21: ='01'!C21 -> 0 | D21: ='01'!D21 -> 8.7766239e-11 | E21: 33.456112 | F21: 0 | G21: =E21+'01'!G21 -> 68.627564 | H21: =F21+'01'!H21 -> 0 | I21: =IFERROR((H21/G21),0) -> 0 | J21: =IFERROR(SUMIF(A102:A115,A21,E102:E115),0) -> 0 | K21: =J21+'01'!K21 -> 0 | L21: =D21+H21-K21+M21 -> 8.7766239e-11
A22: AMD - 6 (навал) | C22: ='01'!C22 -> 1100 | D22: ='01'!D22 -> 2833.7506 | E22: 0 | F22: 0 | G22: =E22+'01'!G22 -> 0 | H22: =F22+'01'!H22 -> 0 | J22: =IFERROR(SUMIF(A103:A123,A22,E103:E123),0)+E109 -> 210.2 | K22: =J22+'01'!K22 -> 659.8 | L22: =D22+H22-K22+M22 -> 2173.9506
A23: Тара: МКР | B23: т | C23: ='01'!C23 -> 0 | D23: ='01'!D23 -> 52 | E23: 0 | F23: =SUM(F24:F29) -> 0 | G23: =E23+'01'!G23 -> 0 | H23: =SUM(H24:H29) -> 0 | I23: =IFERROR((H23/G23),0) -> 0 | J23: =SUM(J24:J29) -> 0 | K23: =J23+'01'!K23 -> 0 | L23: =D23+H23-K23+M23 -> 52
A24: ЦЕМ II/А-К (З-И) 42,5Н | B24: т | D24: ='01'!D24 -> 0 | F24: 0 | G24: =E24+'01'!G24 -> 0 | H24: =F24+'01'!H24 -> 0 | J24: 0 | K24: =J24+'01'!K24 -> 0 | L24: =D24+H24-K24+M24 -> 0
A25: ЦEМ II/B-K(З-И) 32,5H | B25: т | D25: ='01'!D25 -> 16 | F25: 0 | G25: =E25+'01'!G25 -> 0 | H25: =F25+'01'!H25 -> 0 | J25: 0 | K25: =J25+'01'!K25 -> 0 | L25: =D25+H25-K25+M25 -> 16
A26: ='01'!A26 -> ЦEМ I 52,5H Портландцемент (МКР) | B26: т | D26: ='01'!D26 -> 36 | F26: 0 | G26: =E26+'01'!G26 -> 0 | H26: =F26+'01'!H26 -> 0 | J26: 0 | K26: =J26+'01'!K26 -> 0 | L26: =D26+H26-K26+M26 -> 36
A27: ='01'!A27 -> ЦЕМ I 42.5Н | B27: т | D27: ='01'!D27 -> 0 | F27: 0 | G27: =E27+'01'!G27 -> 0 | H27: =F27+'01'!H27 -> 0 | K27: =J27+'01'!K27 -> 0 | L27: =D27+H27-K27+M27 -> 0
B28: т | F28: =J28 -> 0 | G28: =E28+'01'!G28 -> 0 | H28: =F28+'01'!H28 -> 0 | K28: =J28+'01'!K28 -> 0 | L28: =D28+H28-K28+M28 -> 0
B29: т | F29: =J29 -> 0 | G29: =E29+'01'!G29 -> 0 | H29: =F29+'01'!H29 -> 0 | K29: =J29+'01'!K29 -> 0 | L29: =D29+H29-K29+M29 -> 0
A30: Тара: паллеты | B30: т | D30: ='01'!D30 -> 1513.6 | F30: =SUM(F31:F37) -> 357.28 | G30: =E30+'01'!G30 -> 0 | H30: =SUM(H31:H37) -> 554.4 | I30: =IFERROR((H30/G30),0) -> 0 | J30: =SUM(J31:J37) -> 161.92 | K30: =J30+'01'!K30 -> 681.12 | L30: =D30+H30-K30+M30 -> 1386.88
A31: ЦЕМ II/А-К (З-И) 42,5Н | B31: т | D31: ='01'!D31 -> 0 | F31: 0 | G31: =E31+'01'!G31 -> 0 | H31: =F31+'01'!H31 -> 0 | J31: 0 | K31: =J31+'01'!K31 -> 0 | L31: =D31+H31-K31+M31 -> 0
A32: ЦEМ II/B-K(З-И) 42,5H | B32: т | D32: ='01'!D32 -> 1508.32 | F32: 357.28 | G32: =E32+'01'!G32 -> 0 | H32: =F32+'01'!H32 -> 554.4 | J32: 161.92 | K32: =J32+'01'!K32 -> 681.12 | L32: =D32+H32-K32+M32 -> 1381.6
A33: ='01'!A33 -> ЦЕМ I 52.5Н | B33: т | D33: ='01'!D33 -> 5.28 | F33: 0 | G33: =E33+'01'!G33 -> 0 | H33: =F33+'01'!H33 -> 0 | J33: 0 | K33: =J33+'01'!K33 -> 0 | L33: =D33+H33-K33+M33 -> 5.28
A34: ='01'!A34 -> ЦЕМ I 42.5Н | B34: т | D34: ='01'!D34 -> 0 | F34: 0 | G34: =E34+'01'!G34 -> 0 | H34: =F34+'01'!H34 -> 0 | K34: =J34+'01'!K34 -> 0 | L34: =D34+H34-K34+M34 -> 0
B35: т | F35: =J35 -> 0 | G35: =E35+'01'!G35 -> 0 | H35: =F35+'01'!H35 -> 0 | K35: =J35+'01'!K35 -> 0 | L35: =D35+H35-K35+M35 -> 0
A36: Песок природный | B36: т | C36: ='01'!C36 -> 3500 | D36: ='01'!D36 -> 1673.24 | F36: =J36 -> 0 | G36: =E36+'01'!G36 -> 0 | H36: =F36+'01'!H36 -> 0 | J36: 0 | K36: =J36+'01'!K36 -> 0 | L36: =D36+H36-K36+M36 -> 1673.24
A37: Щебень фракции 5-20 | B37: т | C37: ='01'!C37 -> 0 | D37: ='01'!D37 -> 294.64 | F37: =J37 -> 0 | G37: =E37+'01'!G37 -> 0 | H37: =F37+'01'!H37 -> 0 | J37: 0 | K37: =J37+'01'!K37 -> 0 | L37: =D37+H37-K37+M37 -> 294.64
A38: Известняк общий: | B38: т | C38: ='01'!C38 -> 153958.11 | D38: ='01'!D38 -> 1756.983 | E38: =C38/31 -> 4966.3906 | F38: =SUM(F39:F42) -> 3560.0223 | G38: =E38+'01'!G38 -> 9932.7811 | H38: =SUM(H39:H42) -> 6008.2119 | I38: =IFERROR((H38/G38),0) -> 0.60488718 | J38: =SUM(J39:J40) -> 2347.0223 | K38: =SUM(K39:K40) -> 4795.2119 | L38: =D38+H38-K38 -> 2969.983
A39: известняк на шатровый склад | B39: т | F39: 2347.0223 | H39: =F39+'01'!H39 -> 4795.2119 | J39: =F39 -> 2347.0223 | K39: =J39+'01'!K39 -> 4795.2119
A40: известняк на помол | B40: т | F40: 1213 | H40: =F40+'01'!H40 -> 1213 | J40: 0 | K40: =J40+'01'!K40 -> 0
...

Sheet 03
A1: =CONCATENATE("Ежедневный отчет производства и отгрузки за 03 ",Q1) -> Ежедневный отчет производства и отгрузки за 03 август | Q1: август
Q2: 31
A3: Наименование | B3: ЕдИзм | C3: План на месяц | D3: Остатки на складе на начало месяца | E3: Производство/поступление | J3: Отгружено со склада/отпущено в производство/перемещение | L3: Остаток на складе на конец суток | M3: Акты ОКК о переводе марок/перемещение между складами | N3: Перемещения | O3: Комментарии
E4: план на сутки | F4: факт за сутки | G4: план с начала месяца | H4: факт с начала месяца | I4: % | J4: факт за сутки | K4: факт с начала месяца
A5: Клинкер всего | B5: т | C5: =C6+C9 -> 160800 | D5: =D6+D9+D8 -> 143025.21 | E5: =E6+E9 -> 6700 | F5: =F6+F9 -> 6335.2598 | G5: =G6+G9 -> 20100 | H5: =H6+H9 -> 16874.071 | I5: =IFERROR((H5/G5),0) -> 0.83950604 | J5: =J6+J9 -> 3705.5798 | K5: =K6+K9+K8 -> 17027.104 | L5: =L6+L9+L8 -> 142872.18
A6: Клинкер грейферный склад | B6: т | C6: ='01'!C6 -> 0 | D6: ='01'!D6 -> 15952.92 | E6: 0 | G6: =E6+'02'!G6 -> 0 | H6: =F6+'02'!H6 -> 0 | K6: =J6+'02'!K6 -> 0 | L6: =D6+H6-K6-M6-N6 -> 15952.92 | N6: 0
A7: Клинкер некондиция (шихта) | B7: т | D7: ='01'!D7 -> 0 | F7: 0 | H7: =F7+'02'!H7 -> 0 | K7: =J7+'02'!K7 -> 0 | L7: =D7+H7-K7-M7-N7 -> 0
A8: клинкер некондиционный склад БСУ | B8: т | D8: ='01'!D8 -> 0 | H8: =F8+'02'!H8 -> 0 | K8: =J8+'02'!K8 -> 0 | L8: =D8+H8-K8 -> 0
A9: Клинкер сухой линии в т.ч.: | B9: т | C9: ='01'!C9 -> 160800 | D9: ='01'!D9 -> 127072.29 | E9: 6700 | F9: =F10+F11+F12+F13 -> 6335.2598 | G9: =E9+'02'!G9 -> 20100 | H9: =F9+'02'!H9 -> 16874.071 | I9: =IFERROR((H9/G9),0) -> 0.83950604 | J9: =J10+J11+J12+J13 -> 3705.5798 | K9: =K10+K11+K12+K13 -> 17027.104 | L9: =D9+H9-K9+M9+N9 -> 126919.26 | N9: 0
A10: клинкер в силосе | B10: т | D10: ='01'!D10 -> 56300.274 | F10: 6335.2598 | G10: =E10+'02'!G10 -> 0 | H10: =F10+'02'!H10 -> 16874.071 | J10: 3705.5798 | K10: =J10+'02'!K10 -> 17027.104 | L10: =D10+H10-K10+M10-N10 -> 56147.242
A11: Клинкер СС грейферный склад | B11: т | D11: ='01'!D11 -> 18224.017 | G11: =E11+'02'!G11 -> 0 | H11: =F11+'02'!H11 -> 0 | J11: 0 | K11: =J11+'02'!K11 -> 0 | L11: =D11+H11-K11+M11-N11 -> 18224.017
A12: клинкер на площадку (за шатровый склад) | B12: т | D12: ='01'!D12 -> 52548.003 | E12: =C12/31 -> 0 | G12: =E12+'02'!G12 -> 0 | H12: =F12+'02'!H12 -> 0 | K12: =J12+'02'!K12 -> 0 | L12: =D12+H12-K12+M12-N12 -> 52548.003
A13: клинкер на площадку (лессовый) | B13: т | D13: ='01'!D13 -> 0 | H13: =F13+'02'!H13 -> 0 | K13: =J13+'02'!K13 -> 0 | L13: =D13+H13-K13+M13-N13 -> 0
A14: Цемент в силосах всего, в том числе: | B14: т | C14: =SUM(C15:C21) -> 195040 | D14: ='01'!D14 -> 25904.614 | E14: =SUM(E15:E21) -> 6561 | F14: =SUM(F15:F21) -> 4117.5269 | G14: =SUM(G15:G21) -> 16403 | H14: =SUM(H15:H21) -> 18857.688 | I14: =IFERROR((H14/G14),0) -> 1.1496487 | J14: =SUM(J15:J21) -> 4921.76 | K14: =SUM(K15:K21) -> 16699.43 | L14: =SUM(L15:L21) -> 28062.873 | S14: Клинкер фактор | T14: =J5/F14 -> 0.89995278
A15: ЦЕМ II/А-Г 32.5Н | B15: т | C15: ='01'!C15 -> 0 | D15: ='01'!D15 -> 0 | E15: 0 | F15: 0 | G15: =E15+'02'!G15 -> 0 | H15: =F15+'02'!H15 -> 0 | I15: =IFERROR((H15/G15),0) -> 0 | J15: 0 | K15: =J15+'02'!K15 -> 0 | L15: =D15+H15-K15+M15 -> 0
A16: ЦEМ II/B-K(З-И) 42,5H | B16: т | C16: ='01'!C16 -> 44352 | D16: ='01'!D16 -> 6069.3573 | E16: 1491.9682 | F16: 744.77179 | G16: =E16+'02'!G16 -> 3730.0341 | H16: =F16+'02'!H16 -> 3228.5002 | I16: =IFERROR((H16/G16),0) -> 0.86554174 | J16: =IFERROR(SUMIF(A101:A114,A16,E101:E114),0)+E111+E112+E113 -> 875.96 | K16: =J16+'02'!K16 -> 2894.23 | L16: =D16+H16-K16+M16 -> 6403.6275
A17: AMD - 1000 | B17: т | C17: ='01'!C17 -> 0 | D17: ='01'!D17 -> 483.2374 | E17: 0 | F17: 0 | G17: =E17+'02'!G17 -> 0 | H17: =F17+'02'!H17 -> 0 | I17: =IFERROR((H17/G17),0) -> 0 | J17: =IFERROR(SUMIF(A102:A115,A17,E102:E115),0)+E116+E119+E121+E114 -> 0 | K17: =J17+'02'!K17 -> 0 | L17: =D17+H17-K17+M17 -> 483.2374 | S17: Коэф. мука-клинкер | T17: =O51/F5 -> 1.632753
A18: ЦEМ II/B-K(З-И) 32,5H | B18: т | C18: ='01'!C18 -> 1360 | D18: ='01'!D18 -> 3183.2381 | F18: 0 | G18: =E18+'02'!G18 -> 0 | H18: =F18+'02'!H18 -> 0 | I18: =IFERROR((H18/G18),0) -> 0 | J18: =IFERROR(SUMIF(A102:A115,A18,E102:E115),0)+E118+E120 -> 0 | K18: =J18+'02'!K18 -> 0 | L18: =D18+H18-K18+M18 -> 3183.2381
A19: ='01'!A19 -> ЦЕМ I 52.5Н | B19: т | C19: ='01'!C19 -> 145770 | D19: ='01'!D19 -> 12764.734 | E19: 4903.594 | F19: 3372.7551 | G19: =E19+'02'!G19 -> 12259.359 | H19: =F19+'02'!H19 -> 15629.188 | I19: =IFERROR((H19/G19),0) -> 1.2748781 | J19: =IFERROR(SUMIF(A102:A115,A19,E102:E115),0)+E117+E115+E122 -> 3703.2 | K19: =J19+'02'!K19 -> 13235.55 | L19: =D19+H19-K19+M19 -> 15158.372
A20: ЦЕМ I 42.5Н СС | B20: т | C20: ='01'!C20 -> 3558 | D20: ='01'!D20 -> 3404.048 | E20: 119.68846 | F20: 0 | G20: =E20+'02'!G20 -> 299.23028 | H20: =F20+'02'!H20 -> 0 | I20: =IFERROR((H20/G20),0) -> 0 | J20: =IFERROR(SUMIF(A102:A115,A20,E102:E115),0) -> 342.6 | K20: =J20+'02'!K20 -> 569.65 | L20: =D20+H20-K20+M20 -> 2834.398
A21: ='01'!A21 -> ЦЕМ I 42.5Н | B21: т | C21: ='01'!C21 -> 0 | D21: ='01'!D21 -> 8.7766239e-11 | E21: 45.749385 | F21: 0 | G21: =E21+'02'!G21 -> 114.37695 | H21: =F21+'02'!H21 -> 0 | I21: =IFERROR((H21/G21),0) -> 0 | J21: =IFERROR(SUMIF(A102:A115,A21,E102:E115),0) -> 0 | K21: =J21+'02'!K21 -> 0 | L21: =D21+H21-K21+M21 -> 8.7766239e-11
A22: AMD - 6 (навал) | C22: ='01'!C22 -> 1100 | D22: ='01'!D22 -> 2833.7506 | E22: 0 | F22: 2130.1045 | G22: =E22+'02'!G22 -> 0 | H22: =F22+'02'!H22 -> 2130.1045 | J22: =IFERROR(SUMIF(A103:A123,A22,E103:E123),0)+E109 -> 73.45 | K22: =J22+'02'!K22 -> 733.25 | L22: =D22+H22-K22+M22 -> 4230.6051
A23: Тара: МКР | B23: т | C23: ='01'!C23 -> 0 | D23: ='01'!D23 -> 52 | E23: 0 | F23: =SUM(F24:F29) -> 0 | G23: =E23+'02'!G23 -> 0 | H23: =SUM(H24:H29) -> 0 | I23: =IFERROR((H23/G23),0) -> 0 | J23: =SUM(J24:J29) -> 20 | K23: =J23+'02'!K23 -> 20 | L23: =D23+H23-K23+M23 -> 32
A24: ЦЕМ II/А-К (З-И) 42,5Н | B24: т | D24: ='01'!D24 -> 0 | F24: 0 | G24: =E24+'02'!G24 -> 0 | H24: =F24+'02'!H24 -> 0 | J24: 0 | K24: =J24+'02'!K24 -> 0 | L24: =D24+H24-K24+M24 -> 0
A25: ЦEМ II/B-K(З-И) 32,5H | B25: т | D25: ='01'!D25 -> 16 | F25: 0 | G25: =E25+'02'!G25 -> 0 | H25: =F25+'02'!H25 -> 0 | J25: 20 | K25: =J25+'02'!K25 -> 20 | L25: =D25+H25-K25+M25 -> -4
A26: ='01'!A26 -> ЦEМ I 52,5H Портландцемент (МКР) | B26: т | D26: ='01'!D26 -> 36 | F26: 0 | G26: =E26+'02'!G26 -> 0 | H26: =F26+'02'!H26 -> 0 | J26: 0 | K26: =J26+'02'!K26 -> 0 | L26: =D26+H26-K26+M26 -> 36
A27: ='01'!A27 -> ЦЕМ I 42.5Н | B27: т | D27: ='01'!D27 -> 0 | F27: 0 | G27: =E27+'02'!G27 -> 0 | H27: =F27+'02'!H27 -> 0 | K27: =J27+'02'!K27 -> 0 | L27: =D27+H27-K27+M27 -> 0
B28: т | F28: =J28 -> 0 | G28: =E28+'02'!G28 -> 0 | H28: =F28+'02'!H28 -> 0 | K28: =J28+'02'!K28 -> 0 | L28: =D28+H28-K28+M28 -> 0
B29: т | F29: =J29 -> 0 | G29: =E29+'02'!G29 -> 0 | H29: =F29+'02'!H29 -> 0 | K29: =J29+'02'!K29 -> 0 | L29: =D29+H29-K29+M29 -> 0
A30: Тара: паллеты | B30: т | D30: ='01'!D30 -> 1513.6 | F30: =SUM(F31:F37) -> 0 | G30: =E30+'02'!G30 -> 0 | H30: =SUM(H31:H37) -> 554.4 | I30: =IFERROR((H30/G30),0) -> 0 | J30: =SUM(J31:J37) -> 212.96 | K30: =J30+'02'!K30 -> 894.08 | L30: =D30+H30-K30+M30 -> 1173.92
A31: ЦЕМ II/А-К (З-И) 42,5Н | B31: т | D31: ='01'!D31 -> 0 | F31: 0 | G31: =E31+'02'!G31 -> 0 | H31: =F31+'02'!H31 -> 0 | J31: 0 | K31: =J31+'02'!K31 -> 0 | L31: =D31+H31-K31+M31 -> 0
A32: ЦEМ II/B-K(З-И) 42,5H | B32: т | D32: ='01'!D32 -> 1508.32 | F32: 0 | G32: =E32+'02'!G32 -> 0 | H32: =F32+'02'!H32 -> 554.4 | J32: 212.96 | K32: =J32+'02'!K32 -> 894.08 | L32: =D32+H32-K32+M32 -> 1168.64
A33: ='01'!A33 -> ЦЕМ I 52.5Н | B33: т | D33: ='01'!D33 -> 5.28 | F33: 0 | G33: =E33+'02'!G33 -> 0 | H33: =F33+'02'!H33 -> 0 | J33: 0 | K33: =J33+'02'!K33 -> 0 | L33: =D33+H33-K33+M33 -> 5.28
A34: ='01'!A34 -> ЦЕМ I 42.5Н | B34: т | D34: ='01'!D34 -> 0 | F34: 0 | G34: =E34+'02'!G34 -> 0 | H34: =F34+'02'!H34 -> 0 | K34: =J34+'02'!K34 -> 0 | L34: =D34+H34-K34+M34 -> 0
B35: т | F35: =J35 -> 0 | G35: =E35+'02'!G35 -> 0 | H35: =F35+'02'!H35 -> 0 | K35: =J35+'02'!K35 -> 0 | L35: =D35+H35-K35+M35 -> 0
A36: Песок природный | B36: т | C36: ='01'!C36 -> 3500 | D36: ='01'!D36 -> 1673.24 | F36: =J36 -> 0 | G36: =E36+'02'!G36 -> 0 | H36: =F36+'02'!H36 -> 0 | J36: 0 | K36: =J36+'02'!K36 -> 0 | L36: =D36+H36-K36+M36 -> 1673.24
A37: Щебень фракции 5-20 | B37: т | C37: ='01'!C37 -> 0 | D37: ='01'!D37 -> 294.64 | F37: =J37 -> 0 | G37: =E37+'02'!G37 -> 0 | H37: =F37+'02'!H37 -> 0 | J37: 0 | K37: =J37+'02'!K37 -> 0 | L37: =D37+H37-K37+M37 -> 294.64
A38: Известняк общий: | B38: т | C38: ='01'!C38 -> 153958.11 | D38: ='01'!D38 -> 1756.983 | E38: =C38/31 -> 4966.3906 | F38: =SUM(F39:F42) -> 3124.3589 | G38: =E38+'02'!G38 -> 14899.172 | H38: =F38+'02'!H38 -> 9132.5708 | I38: =IFERROR((H38/G38),0) -> 0.61295829 | J38: =SUM(J39:J40) -> 4288.3589 | K38: =J38+'02'!K38 -> 9083.5708 | L38: =D38+H38-K38 -> 1805.983
A39: известняк на шатровый склад | B39: т | F39: 2045.3589 | H39: =F39+'02'!H39 -> 6840.5708 | J39: =F39 -> 2045.3589 | K39: =J39+'02'!K39 -> 6840.5708
A40: известняк на помол | B40: т | F40: 1079 | H40: =F40+'02'!H40 -> 2292 | J40: 2243 | K40: =J40+'02'!K40 -> 2243
...

Sheet 04
A1: =CONCATENATE("Ежедневный отчет производства и отгрузки за 04 ",Q1) -> Ежедневный отчет производства и отгрузки за 04 август | Q1: август
Q2: 31
A3: Наименование | B3: ЕдИзм | C3: План на месяц | D3: Остатки на складе на начало месяца | E3: Производство/поступление | J3: Отгружено со склада/отпущено в производство/перемещение | L3: Остаток на складе на конец суток | M3: Акты ОКК о переводе марок/перемещение между складами | N3: Перемещения | O3: Комментарии
E4: план на сутки | F4: факт за сутки | G4: план с начала месяца | H4: факт с начала месяца | I4: % | J4: факт за сутки | K4: факт с начала месяца
A5: Клинкер всего | B5: т | C5: =C6+C9 -> 160800 | D5: =D6+D9+D8 -> 143025.21 | E5: =E6+E9 -> 6700 | F5: =F6+F9 -> 0 | G5: =G6+G9 -> 26800 | H5: =H6+H9 -> 16874.071 | I5: =IFERROR((H5/G5),0) -> 0.62962953 | J5: =J6+J9 -> 0 | K5: =K6+K9+K8 -> 17027.104 | L5: =L6+L9+L8 -> 142872.18
A6: Клинкер грейферный склад | B6: т | C6: ='01'!C6 -> 0 | D6: ='01'!D6 -> 15952.92 | E6: 0 | G6: =E6+'03'!G6 -> 0 | H6: =F6+'03'!H6 -> 0 | K6: =J6+'03'!K6 -> 0 | L6: =D6+H6-K6-M6-N6 -> 15952.92 | N6: 0
A7: Клинкер некондиция (шихта) | B7: т | D7: ='01'!D7 -> 0 | F7: 0 | H7: =F7+'03'!H7 -> 0 | K7: =J7+'03'!K7 -> 0 | L7: =D7+H7-K7-M7-N7 -> 0
A8: клинкер некондиционный склад БСУ | B8: т | D8: ='01'!D8 -> 0 | H8: =F8+'03'!H8 -> 0 | K8: =J8+'03'!K8 -> 0 | L8: =D8+H8-K8 -> 0
A9: Клинкер сухой линии в т.ч.: | B9: т | C9: ='01'!C9 -> 160800 | D9: ='01'!D9 -> 127072.29 | E9: 6700 | F9: =F10+F11+F12+F13 -> 0 | G9: =E9+'03'!G9 -> 26800 | H9: =F9+'03'!H9 -> 16874.071 | I9: =IFERROR((H9/G9),0) -> 0.62962953 | J9: =J10+J11+J12+J13 -> 0 | K9: =J9+'03'!K9 -> 17027.104 | L9: =D9+H9-K9+M9+N9 -> 126919.26 | N9: 0 | Q9: -23266.572 | R9: =J9-Q9 -> 23266.572
A10: клинкер в силосе | B10: т | D10: ='01'!D10 -> 56300.274 | F10: 0 | G10: =E10+'03'!G10 -> 0 | H10: =F10+'03'!H10 -> 16874.071 | J10: 0 | K10: =J10+'03'!K10 -> 17027.104 | L10: =D10+H10-K10+M10-N10 -> 56147.242
A11: Клинкер СС грейферный склад | B11: т | D11: ='01'!D11 -> 18224.017 | G11: =E11+'03'!G11 -> 0 | H11: =F11+'03'!H11 -> 0 | J11: 0 | K11: =J11+'03'!K11 -> 0 | L11: =D11+H11-K11+M11-N11 -> 18224.017
A12: клинкер на площадку (за шатровый склад) | B12: т | D12: ='01'!D12 -> 52548.003 | E12: =C12/31 -> 0 | G12: =E12+'03'!G12 -> 0 | H12: =F12+'03'!H12 -> 0 | I12: =IFERROR((H12/G12),0) -> 0 | K12: =J12+'03'!K12 -> 0 | L12: =D12+H12-K12+M12-N12 -> 52548.003
A13: клинкер на площадку (лессовый) | B13: т | D13: ='01'!D13 -> 0 | G13: =E13+'03'!G13 -> 0 | H13: =F13+'03'!H13 -> 0 | K13: =J13+'03'!K13 -> 0 | L13: =D13+H13-K13+M13-N13 -> 0
A14: Цемент в силосах всего, в том числе: | B14: т | C14: =SUM(C15:C21) -> 195040 | D14: ='01'!D14 -> 25904.614 | E14: =SUM(E15:E21) -> 6607 | F14: =SUM(F15:F21) -> 0 | G14: =SUM(G15:G21) -> 23010 | H14: =SUM(H15:H21) -> 18857.688 | I14: =IFERROR((H14/G14),0) -> 0.81954317 | J14: =SUM(J15:J21) -> 2251.62 | K14: =SUM(K15:K21) -> 18951.05 | L14: =SUM(L15:L21) -> 25811.253 | S14: Клинкер фактор | T14: =J5/F14 -> #DIV/0!
A15: ЦЕМ II/А-Г 32.5Н | B15: т | C15: ='01'!C15 -> 0 | D15: ='01'!D15 -> 0 | E15: 0 | G15: =E15+'03'!G15 -> 0 | H15: =F15+'03'!H15 -> 0 | I15: =IFERROR((H15/G15),0) -> 0 | J15: 0 | K15: =J15+'03'!K15 -> 0 | L15: =D15+H15-K15+M15 -> 0
A16: ЦEМ II/B-K(З-И) 42,5H | B16: т | C16: ='01'!C16 -> 44352 | D16: ='01'!D16 -> 6069.3573 | E16: 1502.4285 | F16: 0 | G16: =E16+'03'!G16 -> 5232.4627 | H16: =F16+'03'!H16 -> 3228.5002 | I16: =IFERROR((H16/G16),0) -> 0.61701352 | J16: =IFERROR(SUMIF(A101:A114,A16,E101:E114),0)+E111+E112+E113 -> 426.62 | K16: =J16+'03'!K16 -> 3320.85 | L16: =D16+H16-K16+M16 -> 5977.0075
A17: AMD - 1000 | B17: т | C17: ='01'!C17 -> 0 | D17: ='01'!D17 -> 483.2374 | E17: 0 | F17: 0 | G17: =E17+'03'!G17 -> 0 | H17: =F17+'03'!H17 -> 0 | I17: =IFERROR((H17/G17),0) -> 0 | J17: =IFERROR(SUMIF(A102:A115,A17,E102:E115),0)+E116+E119+E121+E114 -> 0 | K17: =J17+'03'!K17 -> 0 | L17: =D17+H17-K17+M17 -> 483.2374 | S17: Коэф. мука-клинкер | T17: =O51/F5 -> #DIV/0!
A18: ЦEМ II/B-K(З-И) 32,5H | B18: т | C18: ='01'!C18 -> 1360 | D18: ='01'!D18 -> 3183.2381 | F18: 0 | G18: =E18+'03'!G18 -> 0 | H18: =F18+'03'!H18 -> 0 | I18: =IFERROR((H18/G18),0) -> 0 | J18: =IFERROR(SUMIF(A102:A115,A18,E102:E115),0)+E118+E120 -> 0 | K18: =J18+'03'!K18 -> 0 | L18: =D18+H18-K18+M18 -> 3183.2381
A19: ='01'!A19 -> ЦЕМ I 52.5Н | B19: т | C19: ='01'!C19 -> 145770 | D19: ='01'!D19 -> 12764.734 | E19: 4937.9737 | F19: 0 | G19: =E19+'03'!G19 -> 17197.332 | H19: =F19+'03'!H19 -> 15629.188 | I19: =IFERROR((H19/G19),0) -> 0.90881468 | J19: =IFERROR(SUMIF(A102:A115,A19,E102:E115),0)+E117+E115+E122 -> 1568.05 | K19: =J19+'03'!K19 -> 14803.6 | L19: =D19+H19-K19+M19 -> 13590.322
A20: ЦЕМ I 42.5Н СС | B20: т | C20: ='01'!C20 -> 3558 | D20: ='01'!D20 -> 3404.048 | E20: 120.52761 | F20: 0 | G20: =E20+'03'!G20 -> 419.7579 | H20: =F20+'03'!H20 -> 0 | I20: =IFERROR((H20/G20),0) -> 0 | J20: =IFERROR(SUMIF(A102:A115,A20,E102:E115),0) -> 256.95 | K20: =J20+'03'!K20 -> 826.6 | L20: =D20+H20-K20+M20 -> 2577.448
A21: ='01'!A21 -> ЦЕМ I 42.5Н | B21: т | C21: ='01'!C21 -> 0 | D21: ='01'!D21 -> 8.7766239e-11 | E21: 46.070139 | F21: 0 | G21: =E21+'03'!G21 -> 160.44709 | H21: =F21+'03'!H21 -> 0 | I21: =IFERROR((H21/G21),0) -> 0 | J21: =IFERROR(SUMIF(A102:A115,A21,E102:E115),0) -> 0 | K21: =J21+'03'!K21 -> 0 | L21: =D21+H21-K21+M21 -> 8.7766239e-11
A22: AMD - 6 (навал) | C22: ='01'!C22 -> 1100 | D22: ='01'!D22 -> 2833.7506 | E22: 0 | F22: 0 | G22: =E22+'03'!G22 -> 0 | H22: =F22+'03'!H22 -> 2130.1045 | J22: =IFERROR(SUMIF(A103:A123,A22,E103:E123),0)+E109 -> 23.95 | K22: =J22+'03'!K22 -> 757.2 | L22: =D22+H22-K22+M22 -> 4206.6551
A23: Тара: МКР | B23: т | C23: ='01'!C23 -> 0 | D23: ='01'!D23 -> 52 | E23: 0 | F23: =SUM(F24:F29) -> 0 | G23: =E23+'03'!G23 -> 0 | H23: =SUM(H24:H29) -> 0 | I23: =IFERROR((H23/G23),0) -> 0 | J23: =SUM(J24:J29) -> 0 | K23: =J23+'03'!K23 -> 20 | L23: =D23+H23-K23+M23 -> 32
A24: ЦЕМ II/А-К (З-И) 42,5Н | B24: т | D24: ='01'!D24 -> 0 | F24: 0 | G24: =E24+'03'!G24 -> 0 | H24: =F24+'03'!H24 -> 0 | J24: 0 | K24: =J24+'03'!K24 -> 0 | L24: =D24+H24-K24+M24 -> 0
A25: ЦEМ II/B-K(З-И) 32,5H | B25: т | D25: ='01'!D25 -> 16 | F25: 0 | G25: =E25+'03'!G25 -> 0 | H25: =F25+'03'!H25 -> 0 | J25: 0 | K25: =J25+'03'!K25 -> 20 | L25: =D25+H25-K25+M25 -> -4
A26: ='01'!A26 -> ЦEМ I 52,5H Портландцемент (МКР) | B26: т | D26: ='01'!D26 -> 36 | F26: 0 | G26: =E26+'03'!G26 -> 0 | H26: =F26+'03'!H26 -> 0 | J26: 0 | K26: =J26+'03'!K26 -> 0 | L26: =D26+H26-K26+M26 -> 36
A27: ='01'!A27 -> ЦЕМ I 42.5Н | B27: т | D27: ='01'!D27 -> 0 | F27: 0 | G27: =E27+'03'!G27 -> 0 | H27: =F27+'03'!H27 -> 0 | K27: =J27+'03'!K27 -> 0 | L27: =D27+H27-K27+M27 -> 0
B28: т | F28: =J28 -> 0 | G28: =E28+'03'!G28 -> 0 | H28: =F28+'03'!H28 -> 0 | K28: =J28+'03'!K28 -> 0 | L28: =D28+H28-K28+M28 -> 0
B29: т | F29: =J29 -> 0 | G29: =E29+'03'!G29 -> 0 | H29: =F29+'03'!H29 -> 0 | K29: =J29+'03'!K29 -> 0 | L29: =D29+H29-K29+M29 -> 0
A30: Тара: паллеты | B30: т | D30: ='01'!D30 -> 1513.6 | F30: =SUM(F31:F37) -> 0 | G30: =E30+'03'!G30 -> 0 | H30: =SUM(H31:H37) -> 554.4 | I30: =IFERROR((H30/G30),0) -> 0 | J30: =SUM(J31:J37) -> 100.32 | K30: =J30+'03'!K30 -> 994.4 | L30: =D30+H30-K30+M30 -> 1073.6
A31: ЦЕМ II/А-К (З-И) 42,5Н | B31: т | D31: ='01'!D31 -> 0 | F31: 0 | G31: =E31+'03'!G31 -> 0 | H31: =F31+'03'!H31 -> 0 | J31: 0 | K31: =J31+'03'!K31 -> 0 | L31: =D31+H31-K31+M31 -> 0
A32: ЦEМ II/B-K(З-И) 42,5H | B32: т | D32: ='01'!D32 -> 1508.32 | F32: 0 | G32: =E32+'03'!G32 -> 0 | H32: =F32+'03'!H32 -> 554.4 | J32: 100.32 | K32: =J32+'03'!K32 -> 994.4 | L32: =D32+H32-K32+M32 -> 1068.32
A33: ='01'!A33 -> ЦЕМ I 52.5Н | B33: т | D33: ='01'!D33 -> 5.28 | F33: 0 | G33: =E33+'03'!G33 -> 0 | H33: =F33+'03'!H33 -> 0 | J33: 0 | K33: =J33+'03'!K33 -> 0 | L33: =D33+H33-K33+M33 -> 5.28
A34: ='01'!A34 -> ЦЕМ I 42.5Н | B34: т | D34: ='01'!D34 -> 0 | F34: 0 | G34: =E34+'03'!G34 -> 0 | H34: =F34+'03'!H34 -> 0 | K34: =J34+'03'!K34 -> 0 | L34: =D34+H34-K34+M34 -> 0
B35: т | F35: =J35 -> 0 | G35: =E35+'03'!G35 -> 0 | H35: =F35+'03'!H35 -> 0 | K35: =J35+'03'!K35 -> 0 | L35: =D35+H35-K35+M35 -> 0
A36: Песок природный | B36: т | C36: ='01'!C36 -> 3500 | D36: ='01'!D36 -> 1673.24 | F36: =J36 -> 0 | G36: =E36+'03'!G36 -> 0 | H36: =F36+'03'!H36 -> 0 | J36: 0 | K36: =J36+'03'!K36 -> 0 | L36: =D36+H36-K36+M36 -> 1673.24
A37: Щебень фракции 5-20 | B37: т | C37: ='01'!C37 -> 0 | D37: ='01'!D37 -> 294.64 | F37: =J37 -> 0 | G37: =E37+'03'!G37 -> 0 | H37: =F37+'03'!H37 -> 0 | J37: 0 | K37: =J37+'03'!K37 -> 0 | L37: =D37+H37-K37+M37 -> 294.64
A38: Известняк общий: | B38: т | C38: ='01'!C38 -> 153958.11 | D38: ='01'!D38 -> 1756.983 | E38: =C38/31 -> 4966.3906 | F38: =SUM(F39:F42) -> 0 | G38: =E38+'03'!G38 -> 19865.562 | H38: =F38+'03'!H38 -> 9132.5708 | I38: =IFERROR((H38/G38),0) -> 0.45971872 | J38: =SUM(J39:J40) -> 0 | K38: =J38+'03'!K38 -> 9083.5708 | L38: =D38+H38-K38 -> 1805.983
A39: известняк на шатровый склад | B39: т | F39: 0 | H39: =F39+'03'!H39 -> 6840.5708 | J39: =F39 -> 0 | K39: =J39+'03'!K39 -> 6840.5708 | L39: =D39+H39-K39 -> 0
A40: известняк на помол | B40: т | F40: 0 | H40: =F40+'03'!H40 -> 2292 | J40: 0 | K40: =J40+'03'!K40 -> 2243
...

Sheet 05
A1: =CONCATENATE("Ежедневный отчет производства и отгрузки за 05 ",Q1) -> Ежедневный отчет производства и отгрузки за 05 август | Q1: август
Q2: 31
A3: Наименование | B3: ЕдИзм | C3: План на месяц | D3: Остатки на складе на начало месяца | E3: Производство/поступление | J3: Отгружено со склада/отпущено в производство/перемещение | L3: Остаток на складе на конец суток | M3: Акты ОКК о переводе марок/перемещение между складами | N3: Перемещения | O3: Комментарии
E4: план на сутки | F4: факт за сутки | G4: план с начала месяца | H4: факт с начала месяца | I4: % | J4: факт за сутки | K4: факт с начала месяца
A5: Клинкер всего | B5: т | C5: =C6+C9 -> 160800 | D5: =D6+D9+D8 -> 143025.21 | E5: =E6+E9 -> 6700 | F5: =F6+F9 -> 0 | G5: =G6+G9 -> 33500 | H5: =H6+H9 -> 16874.071 | I5: =IFERROR((H5/G5),0) -> 0.50370362 | J5: =J6+J9 -> 0 | K5: =K6+K9+K8 -> 17027.104 | L5: =L6+L9+L8 -> 142872.18
A6: Клинкер грейферный склад | B6: т | C6: ='01'!C6 -> 0 | D6: ='01'!D6 -> 15952.92 | E6: 0 | G6: =E6+'04'!G6 -> 0 | H6: =F6+'04'!H6 -> 0 | K6: =J6+'04'!K6 -> 0 | L6: =D6+H6-K6-M6-N6 -> 15952.92 | N6: 0
A7: Клинкер некондиция (шихта) | B7: т | D7: ='01'!D7 -> 0 | F7: 0 | H7: =F7+'04'!H7 -> 0 | K7: =J7+'04'!K7 -> 0 | L7: =D7+H7-K7-M7-N7 -> 0
A8: клинкер некондиционный склад БСУ | B8: т | D8: ='01'!D8 -> 0 | H8: =F8+'04'!H8 -> 0 | K8: =J8+'04'!K8 -> 0 | L8: =D8+H8-K8 -> 0
A9: Клинкер сухой линии в т.ч.: | B9: т | C9: ='01'!C9 -> 160800 | D9: ='01'!D9 -> 127072.29 | E9: 6700 | F9: =F10+F11+F12+F13 -> 0 | G9: =E9+'04'!G9 -> 33500 | H9: =F9+'04'!H9 -> 16874.071 | I9: =IFERROR((H9/G9),0) -> 0.50370362 | J9: =J10+J11+J12+J13 -> 0 | K9: =J9+'04'!K9 -> 17027.104 | L9: =D9+H9-K9+M9+N9 -> 126919.26 | N9: 0 | Q9: -23266.572 | R9: =J9-Q9 -> 23266.572
A10: клинкер в силосе | B10: т | D10: ='01'!D10 -> 56300.274 | F10: 0 | G10: =E10+'04'!G10 -> 0 | H10: =F10+'04'!H10 -> 16874.071 | J10: 0 | K10: =J10+'04'!K10 -> 17027.104 | L10: =D10+H10-K10+M10-N10 -> 56147.242
A11: Клинкер СС грейферный склад | B11: т | D11: ='01'!D11 -> 18224.017 | G11: =E11+'04'!G11 -> 0 | H11: =F11+'04'!H11 -> 0 | J11: 0 | K11: =J11+'04'!K11 -> 0 | L11: =D11+H11-K11+M11-N11 -> 18224.017
A12: клинкер на площадку (за шатровый склад) | B12: т | D12: ='01'!D12 -> 52548.003 | E12: =C12/31 -> 0 | G12: =E12+'04'!G12 -> 0 | H12: =F12+'04'!H12 -> 0 | I12: =IFERROR((H12/G12),0) -> 0 | K12: =J12+'04'!K12 -> 0 | L12: =D12+H12-K12+M12-N12 -> 52548.003
A13: клинкер на площадку (лессовый) | B13: т | D13: ='01'!D13 -> 0 | H13: =F13+'04'!H13 -> 0 | K13: =J13+'04'!K13 -> 0 | L13: =D13+H13-K13+M13-N13 -> 0
A14: Цемент в силосах всего, в том числе: | B14: т | C14: =SUM(C15:C21) -> 195040 | D14: ='01'!D14 -> 25904.614 | E14: =SUM(E15:E21) -> 6749 | F14: =SUM(F15:F21) -> 0 | G14: =SUM(G15:G21) -> 29759 | H14: =SUM(H15:H21) -> 18857.688 | I14: =IFERROR((H14/G14),0) -> 0.63368017 | J14: =SUM(J15:J21) -> 0 | K14: =SUM(K15:K21) -> 18951.05 | L14: =SUM(L15:L21) -> 25811.253 | S14: Клинкер фактор | T14: =J5/F14 -> #DIV/0!
A15: ЦЕМ II/А-Г 32.5Н | B15: т | C15: ='01'!C15 -> 0 | D15: ='01'!D15 -> 0 | E15: 0 | F15: 0 | G15: =E15+'04'!G15 -> 0 | H15: =F15+'04'!H15 -> 0 | I15: =IFERROR((H15/G15),0) -> 0 | J15: 0 | K15: =J15+'04'!K15 -> 0 | L15: =D15+H15-K15+M15 -> 0
A16: ЦEМ II/B-K(З-И) 42,5H | B16: т | C16: ='01'!C16 -> 44352 | D16: ='01'!D16 -> 6069.3573 | E16: 1534.7193 | F16: 0 | G16: =E16+'04'!G16 -> 6767.182 | H16: =F16+'04'!H16 -> 3228.5002 | I16: =IFERROR((H16/G16),0) -> 0.47708193 | J16: =IFERROR(SUMIF(A101:A114,A16,E101:E114),0)+E111+E112+E113 -> 0 | K16: =J16+'04'!K16 -> 3320.85 | L16: =D16+H16-K16+M16 -> 5977.0075
A17: AMD - 1000 | B17: т | C17: ='01'!C17 -> 0 | D17: ='01'!D17 -> 483.2374 | E17: 0 | F17: 0 | G17: =E17+'04'!G17 -> 0 | H17: =F17+'04'!H17 -> 0 | I17: =IFERROR((H17/G17),0) -> 0 | J17: =IFERROR(SUMIF(A102:A115,A17,E102:E115),0)+E116+E119+E121+E114 -> 0 | K17: =J17+'04'!K17 -> 0 | L17: =D17+H17-K17+M17 -> 483.2374 | S17: Коэф. мука-клинкер | T17: =O51/F5 -> #DIV/0!
A18: ЦEМ II/B-K(З-И) 32,5H | B18: т | C18: ='01'!C18 -> 1360 | D18: ='01'!D18 -> 3183.2381 | G18: =E18+'04'!G18 -> 0 | H18: =F18+'04'!H18 -> 0 | I18: =IFERROR((H18/G18),0) -> 0 | J18: =IFERROR(SUMIF(A102:A115,A18,E102:E115),0)+E118+E120 -> 0 | K18: =J18+'04'!K18 -> 0 | L18: =D18+H18-K18+M18 -> 3183.2381
A19: ='01'!A19 -> ЦЕМ I 52.5Н | B19: т | C19: ='01'!C19 -> 145770 | D19: ='01'!D19 -> 12764.734 | E19: 5044.1024 | F19: 0 | G19: =E19+'04'!G19 -> 22241.435 | H19: =F19+'04'!H19 -> 15629.188 | I19: =IFERROR((H19/G19),0) -> 0.70270593 | J19: =IFERROR(SUMIF(A102:A115,A19,E102:E115),0)+E117+E115+E122 -> 0 | K19: =J19+'04'!K19 -> 14803.6 | L19: =D19+H19-K19+M19 -> 13590.322
A20: ЦЕМ I 42.5Н СС | B20: т | C20: ='01'!C20 -> 3558 | D20: ='01'!D20 -> 3404.048 | E20: 123.11804 | F20: 0 | G20: =E20+'04'!G20 -> 542.87593 | H20: =F20+'04'!H20 -> 0 | I20: =IFERROR((H20/G20),0) -> 0 | J20: =IFERROR(SUMIF(A102:A115,A20,E102:E115),0) -> 0 | K20: =J20+'04'!K20 -> 826.6 | L20: =D20+H20-K20+M20 -> 2577.448
A21: ='01'!A21 -> ЦЕМ I 42.5Н | B21: т | C21: ='01'!C21 -> 0 | D21: ='01'!D21 -> 8.7766239e-11 | E21: 47.060295 | F21: 0 | G21: =E21+'04'!G21 -> 207.50738 | H21: =F21+'04'!H21 -> 0 | I21: =IFERROR((H21/G21),0) -> 0 | J21: =IFERROR(SUMIF(A102:A115,A21,E102:E115),0) -> 0 | K21: =J21+'04'!K21 -> 0 | L21: =D21+H21-K21+M21 -> 8.7766239e-11
A22: AMD - 6 (навал) | C22: ='01'!C22 -> 1100 | D22: ='01'!D22 -> 2833.7506 | E22: 0 | F22: 0 | G22: =E22+'04'!G22 -> 0 | H22: =F22+'04'!H22 -> 2130.1045 | J22: =IFERROR(SUMIF(A103:A123,A22,E103:E123),0)+E109 -> 0 | K22: =J22+'04'!K22 -> 757.2 | L22: =D22+H22-K22+M22 -> 4206.6551
A23: Тара: МКР | B23: т | C23: ='01'!C23 -> 0 | D23: ='01'!D23 -> 52 | E23: 0 | F23: =SUM(F24:F29) -> 0 | G23: =E23+'04'!G23 -> 0 | H23: =SUM(H24:H29) -> 0 | I23: =IFERROR((H23/G23),0) -> 0 | J23: =SUM(J24:J29) -> 0 | K23: =J23+'04'!K23 -> 20 | L23: =D23+H23-K23+M23 -> 32
A24: ЦЕМ II/А-К (З-И) 42,5Н | B24: т | D24: ='01'!D24 -> 0 | F24: 0 | G24: =E24+'04'!G24 -> 0 | H24: =F24+'04'!H24 -> 0 | J24: 0 | K24: =J24+'04'!K24 -> 0 | L24: =D24+H24-K24+M24 -> 0
A25: ЦEМ II/B-K(З-И) 32,5H | B25: т | D25: ='01'!D25 -> 16 | F25: 0 | G25: =E25+'04'!G25 -> 0 | H25: =F25+'04'!H25 -> 0 | J25: 0 | K25: =J25+'04'!K25 -> 20 | L25: =D25+H25-K25+M25 -> -4
A26: ='01'!A26 -> ЦEМ I 52,5H Портландцемент (МКР) | B26: т | D26: ='01'!D26 -> 36 | F26: 0 | G26: =E26+'04'!G26 -> 0 | H26: =F26+'04'!H26 -> 0 | J26: 0 | K26: =J26+'04'!K26 -> 0 | L26: =D26+H26-K26+M26 -> 36
A27: ='01'!A27 -> ЦЕМ I 42.5Н | B27: т | D27: ='01'!D27 -> 0 | F27: 0 | G27: =E27+'04'!G27 -> 0 | H27: =F27+'04'!H27 -> 0 | K27: =J27+'04'!K27 -> 0 | L27: =D27+H27-K27+M27 -> 0
B28: т | F28: =J28 -> 0 | G28: =E28+'04'!G28 -> 0 | H28: =F28+'04'!H28 -> 0 | K28: =J28+'04'!K28 -> 0 | L28: =D28+H28-K28+M28 -> 0
B29: т | F29: =J29 -> 0 | G29: =E29+'04'!G29 -> 0 | H29: =F29+'04'!H29 -> 0 | K29: =J29+'04'!K29 -> 0 | L29: =D29+H29-K29+M29 -> 0
A30: Тара: паллеты | B30: т | D30: ='01'!D30 -> 1513.6 | F30: =SUM(F31:F37) -> 0 | G30: =E30+'04'!G30 -> 0 | H30: =SUM(H31:H37) -> 554.4 | I30: =IFERROR((H30/G30),0) -> 0 | J30: =SUM(J31:J37) -> 0 | K30: =J30+'04'!K30 -> 994.4 | L30: =D30+H30-K30+M30 -> 1073.6
A31: ЦЕМ II/А-К (З-И) 42,5Н | B31: т | D31: ='01'!D31 -> 0 | F31: 0 | G31: =E31+'04'!G31 -> 0 | H31: =F31+'04'!H31 -> 0 | J31: 0 | K31: =J31+'04'!K31 -> 0 | L31: =D31+H31-K31+M31 -> 0
A32: ЦEМ II/B-K(З-И) 42,5H | B32: т | D32: ='01'!D32 -> 1508.32 | F32: 0 | G32: =E32+'04'!G32 -> 0 | H32: =F32+'04'!H32 -> 554.4 | J32: 0 | K32: =J32+'04'!K32 -> 994.4 | L32: =D32+H32-K32+M32 -> 1068.32
A33: ='01'!A33 -> ЦЕМ I 52.5Н | B33: т | D33: ='01'!D33 -> 5.28 | F33: 0 | G33: =E33+'04'!G33 -> 0 | H33: =F33+'04'!H33 -> 0 | J33: 0 | K33: =J33+'04'!K33 -> 0 | L33: =D33+H33-K33+M33 -> 5.28
A34: ='01'!A34 -> ЦЕМ I 42.5Н | B34: т | D34: ='01'!D34 -> 0 | F34: 0 | G34: =E34+'04'!G34 -> 0 | H34: =F34+'04'!H34 -> 0 | K34: =J34+'04'!K34 -> 0 | L34: =D34+H34-K34+M34 -> 0
B35: т | F35: =J35 -> 0 | G35: =E35+'04'!G35 -> 0 | H35: =F35+'04'!H35 -> 0 | K35: =J35+'04'!K35 -> 0 | L35: =D35+H35-K35+M35 -> 0
A36: Песок природный | B36: т | C36: ='01'!C36 -> 3500 | D36: ='01'!D36 -> 1673.24 | F36: =J36 -> 0 | G36: =E36+'04'!G36 -> 0 | H36: =F36+'04'!H36 -> 0 | J36: 0 | K36: =J36+'04'!K36 -> 0 | L36: =D36+H36-K36+M36 -> 1673.24
A37: Щебень фракции 5-20 | B37: т | C37: ='01'!C37 -> 0 | D37: ='01'!D37 -> 294.64 | F37: =J37 -> 0 | G37: =E37+'04'!G37 -> 0 | H37: =F37+'04'!H37 -> 0 | J37: 0 | K37: =J37+'04'!K37 -> 0 | L37: =D37+H37-K37+M37 -> 294.64
A38: Известняк общий: | B38: т | C38: ='01'!C38 -> 153958.11 | D38: ='01'!D38 -> 1756.983 | E38: =C38/31 -> 4966.3906 | F38: =SUM(F39:F42) -> 0 | G38: =E38+'04'!G38 -> 24831.953 | H38: =F38+'04'!H38 -> 9132.5708 | I38: =IFERROR((H38/G38),0) -> 0.36777497 | J38: =SUM(J39:J40) -> 0 | K38: =J38+'04'!K38 -> 9083.5708 | L38: =D38+H38-K38 -> 1805.983
A39: известняк на шатровый склад | B39: т | F39: 0 | H39: =F39+'04'!H39 -> 6840.5708 | J39: =F39 -> 0 | K39: =J39+'04'!K39 -> 6840.5708 | U39: -2130.1045
A40: известняк на помол | B40: т | F40: 0 | H40: =F40+'04'!H40 -> 2292 | J40: 0 | K40: =J40+'04'!K40 -> 2243
...

Sheet 06
A1: =CONCATENATE("Ежедневный отчет производства и отгрузки за 06 ",Q1) -> Ежедневный отчет производства и отгрузки за 06 август | Q1: август
Q2: 31
A3: Наименование | B3: ЕдИзм | C3: План на месяц | D3: Остатки на складе на начало месяца | E3: Производство/поступление | J3: Отгружено со склада/отпущено в производство/перемещение | L3: Остаток на складе на конец суток | M3: Акты ОКК о переводе марок/перемещение между складами | N3: Перемещения | O3: Комментарии
E4: план на сутки | F4: факт за сутки | G4: план с начала месяца | H4: факт с начала месяца | I4: % | J4: факт за сутки | K4: факт с начала месяца
A5: Клинкер всего | B5: т | C5: =C6+C9 -> 160800 | D5: =D6+D9+D8 -> 143025.21 | E5: =E6+E9 -> 6700 | F5: =F6+F9 -> 0 | G5: =G6+G9 -> 40200 | H5: =H6+H9 -> 16874.071 | I5: =IFERROR((H5/G5),0) -> 0.41975302 | J5: =J6+J9 -> 0 | K5: =K6+K9+K8 -> 17027.104 | L5: =L6+L9+L8 -> 142872.18
A6: Клинкер грейферный склад | B6: т | C6: ='01'!C6 -> 0 | D6: ='01'!D6 -> 15952.92 | E6: 0 | F6: 6671.6154 | G6: =E6+'05'!G6 -> 0 | H6: =F6+'05'!H6 -> 6671.6154 | K6: =J6+'05'!K6 -> 0 | L6: =D6+H6-K6-M6-N6 -> 22624.535 | N6: 0
A7: Клинкер некондиция (шихта) | B7: т | D7: ='01'!D7 -> 0 | F7: 0 | H7: =F7+'05'!H7 -> 0 | K7: =J7+'05'!K7 -> 0 | L7: =D7+H7-K7-M7-N7 -> 0
A8: клинкер некондиционный склад БСУ | B8: т | D8: ='01'!D8 -> 0 | H8: =F8+'05'!H8 -> 0 | K8: =J8+'05'!K8 -> 0 | L8: =D8+H8-K8 -> 0
A9: Клинкер сухой линии в т.ч.: | B9: т | C9: ='01'!C9 -> 160800 | D9: ='01'!D9 -> 127072.29 | E9: 6700 | F9: =F10+F11+F8+F12+F13 -> -6671.6154 | G9: =E9+'05'!G9 -> 40200 | H9: =F9+'05'!H9 -> 10202.456 | I9: =IFERROR((H9/G9),0) -> 0.25379244 | J9: =J10+J11+J12+J13 -> 0 | K9: =J9+'05'!K9 -> 17027.104 | L9: =D9+H9-K9+M9+N9 -> 120247.65 | N9: 0 | Q9: -23266.572 | R9: =J9-Q9 -> 23266.572
A10: клинкер в силосе | B10: т | D10: ='01'!D10 -> 56300.274 | F10: -6671.6154 | G10: =E10+'05'!G10 -> 0 | H10: =F10+'05'!H10 -> 10202.456 | J10: 0 | K10: =J10+'05'!K10 -> 17027.104 | L10: =D10+H10-K10+M10-N10 -> 49475.626
A11: Клинкер СС грейферный склад | B11: т | D11: ='01'!D11 -> 18224.017 | G11: =E11+'05'!G11 -> 0 | H11: =F11+'05'!H11 -> 0 | J11: 0 | K11: =J11+'05'!K11 -> 0 | L11: =D11+H11-K11+M11-N11 -> 18224.017
A12: клинкер на площадку (за шатровый склад) | B12: т | D12: ='01'!D12 -> 52548.003 | E12: =C12/31 -> 0 | G12: =E12+'05'!G12 -> 0 | H12: =F12+'05'!H12 -> 0 | I12: =IFERROR((H12/G12),0) -> 0 | K12: =J12+'05'!K12 -> 0 | L12: =D12+H12-K12+M12-N12 -> 52548.003
A13: клинкер на площадку (лессовый) | B13: т | D13: ='01'!D13 -> 0 | H13: =F13+'05'!H13 -> 0 | K13: =J13+'05'!K13 -> 0 | L13: =D13+H13-K13+M13-N13 -> 0
A14: Цемент в силосах всего, в том числе: | B14: т | C14: =SUM(C15:C21) -> 195040 | D14: ='01'!D14 -> 25904.614 | E14: =SUM(E15:E21) -> 6759 | F14: =SUM(F15:F21) -> 0 | G14: =SUM(G15:G21) -> 36518 | H14: =SUM(H15:H21) -> 18857.688 | I14: =IFERROR((H14/G14),0) -> 0.51639433 | J14: =SUM(J15:J21) -> 0 | K14: =SUM(K15:K21) -> 18951.05 | L14: =SUM(L15:L21) -> 25811.253 | S14: Клинкер фактор | T14: =J5/F14 -> #DIV/0!
A15: ЦЕМ II/А-Г 32.5Н | B15: т | C15: ='01'!C15 -> 0 | D15: ='01'!D15 -> 0 | E15: 0 | F15: 0 | G15: =E15+'05'!G15 -> 0 | H15: =F15+'05'!H15 -> 0 | I15: =IFERROR((H15/G15),0) -> 0 | J15: 0 | K15: =J15+'05'!K15 -> 0 | L15: =D15+H15-K15+M15 -> 0
A16: ЦEМ II/B-K(З-И) 42,5H | B16: т | C16: ='01'!C16 -> 44352 | D16: ='01'!D16 -> 6069.3573 | E16: 1536.9933 | F16: 0 | G16: =E16+'05'!G16 -> 8304.1752 | H16: =F16+'05'!H16 -> 3228.5002 | I16: =IFERROR((H16/G16),0) -> 0.38878036 | J16: =IFERROR(SUMIF(A101:A114,A16,E101:E114),0)+E111+E112+E113 -> 0 | K16: =J16+'05'!K16 -> 3320.85 | L16: =D16+H16-K16+M16 -> 5977.0075
A17: AMD - 1000 | B17: т | C17: ='01'!C17 -> 0 | D17: ='01'!D17 -> 483.2374 | E17: 0 | F17: 0 | G17: =E17+'05'!G17 -> 0 | H17: =F17+'05'!H17 -> 0 | I17: =IFERROR((H17/G17),0) -> 0 | J17: =IFERROR(SUMIF(A102:A115,A17,E102:E115),0)+E116+E119+E121+E114 -> 0 | K17: =J17+'05'!K17 -> 0 | L17: =D17+H17-K17+M17 -> 483.2374 | S17: Коэф. мука-клинкер | T17: =O51/F5 -> #DIV/0!
A18: ЦEМ II/B-K(З-И) 32,5H | B18: т | C18: ='01'!C18 -> 1360 | D18: ='01'!D18 -> 3183.2381 | G18: =E18+'05'!G18 -> 0 | H18: =F18+'05'!H18 -> 0 | I18: =IFERROR((H18/G18),0) -> 0 | J18: =IFERROR(SUMIF(A102:A115,A18,E102:E115),0)+E118+E120 -> 0 | K18: =J18+'05'!K18 -> 0 | L18: =D18+H18-K18+M18 -> 3183.2381
A19: ='01'!A19 -> ЦЕМ I 52.5Н | B19: т | C19: ='01'!C19 -> 145770 | D19: ='01'!D19 -> 12764.734 | E19: 5051.5762 | F19: 0 | G19: =E19+'05'!G19 -> 27293.011 | H19: =F19+'05'!H19 -> 15629.188 | I19: =IFERROR((H19/G19),0) -> 0.57264433 | J19: =IFERROR(SUMIF(A102:A115,A19,E102:E115),0)+E117+E115+E122 -> 0 | K19: =J19+'05'!K19 -> 14803.6 | L19: =D19+H19-K19+M19 -> 13590.322
A20: ЦЕМ I 42.5Н СС | B20: т | C20: ='01'!C20 -> 3558 | D20: ='01'!D20 -> 3404.048 | E20: 123.30046 | F20: 0 | G20: =E20+'05'!G20 -> 666.17639 | H20: =F20+'05'!H20 -> 0 | I20: =IFERROR((H20/G20),0) -> 0 | J20: =IFERROR(SUMIF(A102:A115,A20,E102:E115),0) -> 0 | K20: =J20+'05'!K20 -> 826.6 | L20: =D20+H20-K20+M20 -> 2577.448
A21: ='01'!A21 -> ЦЕМ I 42.5Н | B21: т | C21: ='01'!C21 -> 0 | D21: ='01'!D21 -> 8.7766239e-11 | E21: 47.130025 | F21: 0 | G21: =E21+'05'!G21 -> 254.63741 | H21: =F21+'05'!H21 -> 0 | I21: =IFERROR((H21/G21),0) -> 0 | J21: =IFERROR(SUMIF(A102:A115,A21,E102:E115),0) -> 0 | K21: =J21+'05'!K21 -> 0 | L21: =D21+H21-K21+M21 -> 8.7766239e-11
A22: AMD - 6 (навал) | C22: ='01'!C22 -> 1100 | D22: ='01'!D22 -> 2833.7506 | E22: 0 | F22: 0 | G22: =E22+'05'!G22 -> 0 | H22: =F22+'05'!H22 -> 2130.1045 | J22: =IFERROR(SUMIF(A103:A123,A22,E103:E123),0)+E109 -> 0 | K22: =J22+'05'!K22 -> 757.2 | L22: =D22+H22-K22+M22 -> 4206.6551
A23: Тара: МКР | B23: т | C23: ='01'!C23 -> 0 | D23: ='01'!D23 -> 52 | E23: 0 | F23: =SUM(F24:F29) -> 0 | G23: =E23+'05'!G23 -> 0 | H23: =SUM(H24:H29) -> 0 | I23: =IFERROR((H23/G23),0) -> 0 | J23: =SUM(J24:J29) -> 0 | K23: =J23+'05'!K23 -> 20 | L23: =D23+H23-K23+M23 -> 32
A24: ЦЕМ II/А-К (З-И) 42,5Н | B24: т | D24: ='01'!D24 -> 0 | F24: 0 | G24: =E24+'05'!G24 -> 0 | H24: =F24+'05'!H24 -> 0 | J24: 0 | K24: =J24+'05'!K24 -> 0 | L24: =D24+H24-K24+M24 -> 0
A25: ЦEМ II/B-K(З-И) 32,5H | B25: т | D25: ='01'!D25 -> 16 | F25: 0 | G25: =E25+'05'!G25 -> 0 | H25: =F25+'05'!H25 -> 0 | J25: 0 | K25: =J25+'05'!K25 -> 20 | L25: =D25+H25-K25+M25 -> -4
A26: ='01'!A26 -> ЦEМ I 52,5H Портландцемент (МКР) | B26: т | D26: ='01'!D26 -> 36 | F26: 0 | G26: =E26+'05'!G26 -> 0 | H26: =F26+'05'!H26 -> 0 | J26: 0 | K26: =J26+'05'!K26 -> 0 | L26: =D26+H26-K26+M26 -> 36
A27: ='01'!A27 -> ЦЕМ I 42.5Н | B27: т | D27: ='01'!D27 -> 0 | F27: 0 | G27: =E27+'05'!G27 -> 0 | H27: =F27+'05'!H27 -> 0 | K27: =J27+'05'!K27 -> 0 | L27: =D27+H27-K27+M27 -> 0
B28: т | F28: =J28 -> 0 | G28: =E28+'05'!G28 -> 0 | H28: =F28+'05'!H28 -> 0 | K28: =J28+'05'!K28 -> 0 | L28: =D28+H28-K28+M28 -> 0
B29: т | F29: =J29 -> 0 | G29: =E29+'05'!G29 -> 0 | H29: =F29+'05'!H29 -> 0 | K29: =J29+'05'!K29 -> 0 | L29: =D29+H29-K29+M29 -> 0
A30: Тара: паллеты | B30: т | D30: ='01'!D30 -> 1513.6 | F30: =SUM(F31:F37) -> 0 | G30: =E30+'05'!G30 -> 0 | H30: =SUM(H31:H37) -> 554.4 | I30: =IFERROR((H30/G30),0) -> 0 | J30: =SUM(J31:J37) -> 0 | K30: =J30+'05'!K30 -> 994.4 | L30: =D30+H30-K30+M30 -> 1073.6
A31: ЦЕМ II/А-К (З-И) 42,5Н | B31: т | D31: ='01'!D31 -> 0 | F31: 0 | G31: =E31+'05'!G31 -> 0 | H31: =F31+'05'!H31 -> 0 | J31: 0 | K31: =J31+'05'!K31 -> 0 | L31: =D31+H31-K31+M31 -> 0
A32: ЦEМ II/B-K(З-И) 42,5H | B32: т | D32: ='01'!D32 -> 1508.32 | F32: 0 | G32: =E32+'05'!G32 -> 0 | H32: =F32+'05'!H32 -> 554.4 | J32: 0 | K32: =J32+'05'!K32 -> 994.4 | L32: =D32+H32-K32+M32 -> 1068.32
A33: ='01'!A33 -> ЦЕМ I 52.5Н | B33: т | D33: ='01'!D33 -> 5.28 | F33: 0 | G33: =E33+'05'!G33 -> 0 | H33: =F33+'05'!H33 -> 0 | J33: 0 | K33: =J33+'05'!K33 -> 0 | L33: =D33+H33-K33+M33 -> 5.28
A34: ='01'!A34 -> ЦЕМ I 42.5Н | B34: т | D34: ='01'!D34 -> 0 | F34: 0 | G34: =E34+'05'!G34 -> 0 | H34: =F34+'05'!H34 -> 0 | K34: =J34+'05'!K34 -> 0 | L34: =D34+H34-K34+M34 -> 0
B35: т | F35: =J35 -> 0 | G35: =E35+'05'!G35 -> 0 | H35: =F35+'05'!H35 -> 0 | K35: =J35+'05'!K35 -> 0 | L35: =D35+H35-K35+M35 -> 0
A36: Песок природный | B36: т | C36: ='01'!C36 -> 3500 | D36: ='01'!D36 -> 1673.24 | F36: =J36 -> 0 | G36: =E36+'05'!G36 -> 0 | H36: =F36+'05'!H36 -> 0 | J36: 0 | K36: =J36+'05'!K36 -> 0 | L36: =D36+H36-K36+M36 -> 1673.24
A37: Щебень фракции 5-20 | B37: т | C37: ='01'!C37 -> 0 | D37: ='01'!D37 -> 294.64 | F37: =J37 -> 0 | G37: =E37+'05'!G37 -> 0 | H37: =F37+'05'!H37 -> 0 | J37: 0 | K37: =J37+'05'!K37 -> 0 | L37: =D37+H37-K37+M37 -> 294.64
A38: Известняк общий: | B38: т | C38: ='01'!C38 -> 153958.11 | D38: ='01'!D38 -> 1756.983 | E38: =C38/31 -> 4966.3906 | F38: =SUM(F39:F42) -> 0 | G38: =E38+'05'!G38 -> 29798.343 | H38: =F38+'05'!H38 -> 9132.5708 | I38: =IFERROR((H38/G38),0) -> 0.30647914 | J38: =SUM(J39:J40) -> 0 | K38: =J38+'05'!K38 -> 9083.5708 | L38: =D38+H38-K38 -> 1805.983
A39: известняк на шатровый склад | B39: т | F39: 0 | H39: =F39+'05'!H39 -> 6840.5708 | J39: =F39 -> 0 | K39: =J39+'05'!K39 -> 6840.5708
A40: известняк на помол | B40: т | F40: 0 | H40: =F40+'05'!H40 -> 2292 | J40: 0 | K40: =J40+'05'!K40 -> 2243
...

Sheet 07
A1: =CONCATENATE("Ежедневный отчет производства и отгрузки за 07 ",Q1) -> Ежедневный отчет производства и отгрузки за 07 август | Q1: август
Q2: 31
A3: Наименование | B3: ЕдИзм | C3: План на месяц | D3: Остатки на складе на начало месяца | E3: Производство/поступление | J3: Отгружено со склада/отпущено в производство/перемещение | L3: Остаток на складе на конец суток | M3: Акты ОКК о переводе марок/перемещение между складами | N3: Перемещения | O3: Комментарии
E4: план на сутки | F4: факт за сутки | G4: план с начала месяца | H4: факт с начала месяца | I4: % | J4: факт за сутки | K4: факт с начала месяца
A5: Клинкер всего | B5: т | C5: =C6+C9 -> 160800 | D5: =D6+D9+D8 -> 143025.21 | E5: =E6+E9 -> 6700 | F5: =F6+F9 -> 0 | G5: =G6+G9 -> 46900 | H5: =H6+H9 -> 16874.071 | I5: =IFERROR((H5/G5),0) -> 0.3597883 | J5: =J6+J9 -> 0 | K5: =K6+K9+K8 -> 17027.104 | L5: =L6+L9+L8 -> 142872.18
A6: Клинкер грейферный склад | B6: т | C6: ='01'!C6 -> 0 | D6: ='01'!D6 -> 15952.92 | E6: 0 | G6: =E6+'06'!G6 -> 0 | H6: =F6+'06'!H6 -> 6671.6154 | K6: =J6+'06'!K6 -> 0 | L6: =D6+H6-K6-M6-N6 -> 22624.535 | N6: =N10 -> 0
A7: Клинкер некондиция (шихта) | B7: т | D7: ='01'!D7 -> 0 | F7: 0 | H7: =F7+'06'!H7 -> 0 | K7: =J7+'06'!K7 -> 0 | L7: =D7+H7-K7-M7-N7 -> 0
A8: клинкер некондиционный склад БСУ | B8: т | D8: ='01'!D8 -> 0 | H8: =F8+'06'!H8 -> 0 | K8: =J8+'06'!K8 -> 0 | L8: =D8+H8-K8 -> 0
A9: Клинкер сухой линии в т.ч.: | B9: т | C9: ='01'!C9 -> 160800 | D9: ='01'!D9 -> 127072.29 | E9: 6700 | F9: =F10+F8+F12+F13+F11 -> 0 | G9: =E9+'06'!G9 -> 46900 | H9: =F9+'06'!H9 -> 10202.456 | I9: =IFERROR((H9/G9),0) -> 0.21753637 | J9: =J10+J11+J12+J13 -> 0 | K9: =J9+'06'!K9 -> 17027.104 | L9: =D9+H9-K9+M9+N9 -> 120247.65 | N9: 0 | Q9: -23266.572 | R9: =J9-Q9 -> 23266.572
A10: клинкер в силосе | B10: т | D10: ='01'!D10 -> 56300.274 | F10: 0 | G10: =E10+'06'!G10 -> 0 | H10: =F10+'06'!H10 -> 10202.456 | J10: 0 | K10: =J10+'06'!K10 -> 17027.104 | L10: =D10+H10-K10+M10+N10 -> 49475.626
A11: Клинкер СС грейферный склад | B11: т | D11: ='01'!D11 -> 18224.017 | G11: =E11+'06'!G11 -> 0 | H11: =F11+'06'!H11 -> 0 | J11: 0 | K11: =J11+'06'!K11 -> 0 | L11: =D11+H11-K11+M11-N11 -> 18224.017
A12: клинкер на площадку (за шатровый склад) | B12: т | D12: ='01'!D12 -> 52548.003 | E12: =C12/31 -> 0 | G12: =E12+'06'!G12 -> 0 | H12: =F12+'06'!H12 -> 0 | I12: =IFERROR((H12/G12),0) -> 0 | K12: =J12+'06'!K12 -> 0 | L12: =D12+H12-K12+M12-N12 -> 52548.003
A13: клинкер на площадку (лессовый) | B13: т | D13: ='01'!D13 -> 0 | H13: =F13+'06'!H13 -> 0 | K13: =J13+'06'!K13 -> 0 | L13: =D13+H13-K13+M13-N13 -> 0
A14: Цемент в силосах всего, в том числе: | B14: т | C14: =SUM(C15:C21) -> 195040 | D14: ='01'!D14 -> 25904.614 | E14: =SUM(E15:E21) -> 6639 | F14: =SUM(F15:F21) -> 0 | G14: =SUM(G15:G21) -> 43157 | H14: =SUM(H15:H21) -> 18857.688 | I14: =IFERROR((H14/G14),0) -> 0.4369555 | J14: =SUM(J15:J21) -> 0 | K14: =SUM(K15:K21) -> 18951.05 | L14: =SUM(L15:L21) -> 25811.253 | S14: Клинкер фактор | T14: =J5/F14 -> #DIV/0!
A15: ЦЕМ II/А-Г 32.5Н | B15: т | C15: ='01'!C15 -> 0 | D15: ='01'!D15 -> 0 | E15: 0 | F15: 0 | G15: =E15+'06'!G15 -> 0 | H15: =F15+'06'!H15 -> 0 | I15: =IFERROR((H15/G15),0) -> 0 | J15: 0 | K15: =J15+'06'!K15 -> 0 | L15: =D15+H15-K15+M15 -> 0
A16: ЦEМ II/B-K(З-И) 42,5H | B16: т | C16: ='01'!C16 -> 44352 | D16: ='01'!D16 -> 6069.3573 | E16: 1509.7053 | F16: 0 | G16: =E16+'06'!G16 -> 9813.8806 | H16: =F16+'06'!H16 -> 3228.5002 | I16: =IFERROR((H16/G16),0) -> 0.32897285 | J16: =IFERROR(SUMIF(A101:A114,A16,E101:E114),0)+E111+E112+E113 -> 0 | K16: =J16+'06'!K16 -> 3320.85 | L16: =D16+H16-K16+M16 -> 5977.0075
A17: AMD - 1000 | B17: т | C17: ='01'!C17 -> 0 | D17: ='01'!D17 -> 483.2374 | E17: 0 | F17: 0 | G17: =E17+'06'!G17 -> 0 | H17: =F17+'06'!H17 -> 0 | I17: =IFERROR((H17/G17),0) -> 0 | J17: =IFERROR(SUMIF(A102:A115,A17,E102:E115),0)+E116+E119+E121+E114 -> 0 | K17: =J17+'06'!K17 -> 0 | L17: =D17+H17-K17+M17 -> 483.2374 | S17: Коэф. мука-клинкер | T17: =O51/F5 -> #DIV/0!
A18: ЦEМ II/B-K(З-И) 32,5H | B18: т | C18: ='01'!C18 -> 1360 | D18: ='01'!D18 -> 3183.2381 | G18: =E18+'06'!G18 -> 0 | H18: =F18+'06'!H18 -> 0 | I18: =IFERROR((H18/G18),0) -> 0 | J18: =IFERROR(SUMIF(A102:A115,A18,E102:E115),0)+E118+E120 -> 0 | K18: =J18+'06'!K18 -> 0 | L18: =D18+H18-K18+M18 -> 3183.2381
A19: ='01'!A19 -> ЦЕМ I 52.5Н | B19: т | C19: ='01'!C19 -> 145770 | D19: ='01'!D19 -> 12764.734 | E19: 4961.89 | F19: 0 | G19: =E19+'06'!G19 -> 32254.901 | H19: =F19+'06'!H19 -> 15629.188 | I19: =IFERROR((H19/G19),0) -> 0.48455235 | J19: =IFERROR(SUMIF(A102:A115,A19,E102:E115),0)+E117+E115+E122 -> 0 | K19: =J19+'06'!K19 -> 14803.6 | L19: =D19+H19-K19+M19 -> 13590.322
A20: ЦЕМ I 42.5Н СС | B20: т | C20: ='01'!C20 -> 3558 | D20: ='01'!D20 -> 3404.048 | E20: 121.11137 | F20: 0 | G20: =E20+'06'!G20 -> 787.28777 | H20: =F20+'06'!H20 -> 0 | I20: =IFERROR((H20/G20),0) -> 0 | J20: =IFERROR(SUMIF(A102:A115,A20,E102:E115),0) -> 0 | K20: =J20+'06'!K20 -> 826.6 | L20: =D20+H20-K20+M20 -> 2577.448
A21: ='01'!A21 -> ЦЕМ I 42.5Н | B21: т | C21: ='01'!C21 -> 0 | D21: ='01'!D21 -> 8.7766239e-11 | E21: 46.293273 | F21: 0 | G21: =E21+'06'!G21 -> 300.93068 | H21: =F21+'06'!H21 -> 0 | I21: =IFERROR((H21/G21),0) -> 0 | J21: =IFERROR(SUMIF(A102:A115,A21,E102:E115),0) -> 0 | K21: =J21+'06'!K21 -> 0 | L21: =D21+H21-K21+M21 -> 8.7766239e-11
A22: AMD - 6 (навал) | C22: ='01'!C22 -> 1100 | D22: ='01'!D22 -> 2833.7506 | E22: 0 | F22: 0 | G22: =E22+'06'!G22 -> 0 | H22: =F22+'06'!H22 -> 2130.1045 | J22: =IFERROR(SUMIF(A103:A123,A22,E103:E123),0)+E109 -> 0 | K22: =J22+'06'!K22 -> 757.2 | L22: =D22+H22-K22+M22 -> 4206.6551
A23: Тара: МКР | B23: т | C23: ='01'!C23 -> 0 | D23: ='01'!D23 -> 52 | E23: 0 | F23: =SUM(F24:F29) -> 0 | G23: =E23+'06'!G23 -> 0 | H23: =SUM(H24:H29) -> 0 | I23: =IFERROR((H23/G23),0) -> 0 | J23: =SUM(J24:J29) -> 0 | K23: =J23+'06'!K23 -> 20 | L23: =D23+H23-K23+M23 -> 32
A24: ЦЕМ II/А-К (З-И) 42,5Н | B24: т | D24: ='01'!D24 -> 0 | F24: 0 | G24: =E24+'06'!G24 -> 0 | H24: =F24+'06'!H24 -> 0 | J24: 0 | K24: =J24+'06'!K24 -> 0 | L24: =D24+H24-K24+M24 -> 0
A25: ЦEМ II/B-K(З-И) 32,5H | B25: т | D25: ='01'!D25 -> 16 | F25: 0 | G25: =E25+'06'!G25 -> 0 | H25: =F25+'06'!H25 -> 0 | J25: 0 | K25: =J25+'06'!K25 -> 20 | L25: =D25+H25-K25+M25 -> -4
